[2024-07-10T09:00:10.510+0000] {local_task_job_runner.py:120} INFO - ::group::Pre task execution logs
[2024-07-10T09:00:10.525+0000] {taskinstance.py:2076} INFO - Dependencies all met for dep_context=non-requeueable deps ti=<TaskInstance: market_etl.load_data_to_postgres manual__2024-07-10T08:55:25.813716+00:00 [queued]>
[2024-07-10T09:00:10.531+0000] {taskinstance.py:2076} INFO - Dependencies all met for dep_context=requeueable deps ti=<TaskInstance: market_etl.load_data_to_postgres manual__2024-07-10T08:55:25.813716+00:00 [queued]>
[2024-07-10T09:00:10.532+0000] {taskinstance.py:2306} INFO - Starting attempt 1 of 4
[2024-07-10T09:00:10.539+0000] {taskinstance.py:2330} INFO - Executing <Task(_PythonDecoratedOperator): load_data_to_postgres> on 2024-07-10 08:55:25.813716+00:00
[2024-07-10T09:00:10.548+0000] {warnings.py:112} WARNING - /home/airflow/.local/lib/python3.12/site-packages/airflow/task/task_runner/standard_task_runner.py:61: DeprecationWarning: This process (pid=134) is multi-threaded, use of fork() may lead to deadlocks in the child.
  pid = os.fork()

[2024-07-10T09:00:10.549+0000] {standard_task_runner.py:63} INFO - Started process 136 to run task
[2024-07-10T09:00:10.550+0000] {standard_task_runner.py:90} INFO - Running: ['airflow', 'tasks', 'run', 'market_etl', 'load_data_to_postgres', 'manual__2024-07-10T08:55:25.813716+00:00', '--job-id', '269', '--raw', '--subdir', 'DAGS_FOLDER/etl.py', '--cfg-path', '/tmp/tmp_cv0fu9_']
[2024-07-10T09:00:10.551+0000] {standard_task_runner.py:91} INFO - Job 269: Subtask load_data_to_postgres
[2024-07-10T09:00:10.608+0000] {task_command.py:426} INFO - Running <TaskInstance: market_etl.load_data_to_postgres manual__2024-07-10T08:55:25.813716+00:00 [running]> on host 514b016b59c3
[2024-07-10T09:00:11.004+0000] {taskinstance.py:2648} INFO - Exporting env vars: AIRFLOW_CTX_DAG_OWNER='airflow' AIRFLOW_CTX_DAG_ID='market_etl' AIRFLOW_CTX_TASK_ID='load_data_to_postgres' AIRFLOW_CTX_EXECUTION_DATE='2024-07-10T08:55:25.813716+00:00' AIRFLOW_CTX_TRY_NUMBER='1' AIRFLOW_CTX_DAG_RUN_ID='manual__2024-07-10T08:55:25.813716+00:00'
[2024-07-10T09:00:11.005+0000] {taskinstance.py:430} INFO - ::endgroup::
[2024-07-10T09:00:11.059+0000] {base.py:84} INFO - Using connection ID 'market_database_conn' for task execution.
[2024-07-10T09:00:11.121+0000] {taskinstance.py:441} INFO - ::group::Post task execution logs
[2024-07-10T09:00:11.122+0000] {taskinstance.py:2905} ERROR - Task failed with exception
Traceback (most recent call last):
  File "/home/airflow/.local/lib/python3.12/site-packages/sqlalchemy/engine/base.py", line 1890, in _execute_context
    self.dialect.do_executemany(
  File "/home/airflow/.local/lib/python3.12/site-packages/sqlalchemy/dialects/postgresql/psycopg2.py", line 982, in do_executemany
    context._psycopg2_fetched_rows = xtras.execute_values(
                                     ^^^^^^^^^^^^^^^^^^^^^
  File "/home/airflow/.local/lib/python3.12/site-packages/psycopg2/extras.py", line 1299, in execute_values
    cur.execute(b''.join(parts))
psycopg2.errors.UndefinedColumn: column "STOCK_ID" of relation "fact_table" does not exist
LINE 1: ...D_PRICE", "Total_Trades", "AVERAGE_TRADED_PRICE", "STOCK_ID"...
                                                             ^


The above exception was the direct cause of the following exception:

Traceback (most recent call last):
  File "/home/airflow/.local/lib/python3.12/site-packages/airflow/models/taskinstance.py", line 465, in _execute_task
    result = _execute_callable(context=context, **execute_callable_kwargs)
             ^^^^^^^^^^^^^^^^^^^^^^^^^^^^^^^^^^^^^^^^^^^^^^^^^^^^^^^^^^^^^
  File "/home/airflow/.local/lib/python3.12/site-packages/airflow/models/taskinstance.py", line 432, in _execute_callable
    return execute_callable(context=context, **execute_callable_kwargs)
           ^^^^^^^^^^^^^^^^^^^^^^^^^^^^^^^^^^^^^^^^^^^^^^^^^^^^^^^^^^^^
  File "/home/airflow/.local/lib/python3.12/site-packages/airflow/models/baseoperator.py", line 401, in wrapper
    return func(self, *args, **kwargs)
           ^^^^^^^^^^^^^^^^^^^^^^^^^^^
  File "/home/airflow/.local/lib/python3.12/site-packages/airflow/decorators/base.py", line 265, in execute
    return_value = super().execute(context)
                   ^^^^^^^^^^^^^^^^^^^^^^^^
  File "/home/airflow/.local/lib/python3.12/site-packages/airflow/models/baseoperator.py", line 401, in wrapper
    return func(self, *args, **kwargs)
           ^^^^^^^^^^^^^^^^^^^^^^^^^^^
  File "/home/airflow/.local/lib/python3.12/site-packages/airflow/operators/python.py", line 235, in execute
    return_value = self.execute_callable()
                   ^^^^^^^^^^^^^^^^^^^^^^^
  File "/home/airflow/.local/lib/python3.12/site-packages/airflow/operators/python.py", line 252, in execute_callable
    return self.python_callable(*self.op_args, **self.op_kwargs)
           ^^^^^^^^^^^^^^^^^^^^^^^^^^^^^^^^^^^^^^^^^^^^^^^^^^^^^
  File "/opt/airflow/dags/etl.py", line 108, in load_data_to_postgres
    fact_table.to_sql(
  File "/home/airflow/.local/lib/python3.12/site-packages/pandas/util/_decorators.py", line 333, in wrapper
    return func(*args, **kwargs)
           ^^^^^^^^^^^^^^^^^^^^^
  File "/home/airflow/.local/lib/python3.12/site-packages/pandas/core/generic.py", line 3008, in to_sql
    return sql.to_sql(
           ^^^^^^^^^^^
  File "/home/airflow/.local/lib/python3.12/site-packages/pandas/io/sql.py", line 788, in to_sql
    return pandas_sql.to_sql(
           ^^^^^^^^^^^^^^^^^^
  File "/home/airflow/.local/lib/python3.12/site-packages/pandas/io/sql.py", line 1958, in to_sql
    total_inserted = sql_engine.insert_records(
                     ^^^^^^^^^^^^^^^^^^^^^^^^^^
  File "/home/airflow/.local/lib/python3.12/site-packages/pandas/io/sql.py", line 1507, in insert_records
    raise err
  File "/home/airflow/.local/lib/python3.12/site-packages/pandas/io/sql.py", line 1498, in insert_records
    return table.insert(chunksize=chunksize, method=method)
           ^^^^^^^^^^^^^^^^^^^^^^^^^^^^^^^^^^^^^^^^^^^^^^^^
  File "/home/airflow/.local/lib/python3.12/site-packages/pandas/io/sql.py", line 1059, in insert
    num_inserted = exec_insert(conn, keys, chunk_iter)
                   ^^^^^^^^^^^^^^^^^^^^^^^^^^^^^^^^^^^
  File "/home/airflow/.local/lib/python3.12/site-packages/pandas/io/sql.py", line 951, in _execute_insert
    result = conn.execute(self.table.insert(), data)
             ^^^^^^^^^^^^^^^^^^^^^^^^^^^^^^^^^^^^^^^
  File "/home/airflow/.local/lib/python3.12/site-packages/sqlalchemy/engine/base.py", line 1385, in execute
    return meth(self, multiparams, params, _EMPTY_EXECUTION_OPTS)
           ^^^^^^^^^^^^^^^^^^^^^^^^^^^^^^^^^^^^^^^^^^^^^^^^^^^^^^
  File "/home/airflow/.local/lib/python3.12/site-packages/sqlalchemy/sql/elements.py", line 334, in _execute_on_connection
    return connection._execute_clauseelement(
           ^^^^^^^^^^^^^^^^^^^^^^^^^^^^^^^^^^
  File "/home/airflow/.local/lib/python3.12/site-packages/sqlalchemy/engine/base.py", line 1577, in _execute_clauseelement
    ret = self._execute_context(
          ^^^^^^^^^^^^^^^^^^^^^^
  File "/home/airflow/.local/lib/python3.12/site-packages/sqlalchemy/engine/base.py", line 1953, in _execute_context
    self._handle_dbapi_exception(
  File "/home/airflow/.local/lib/python3.12/site-packages/sqlalchemy/engine/base.py", line 2134, in _handle_dbapi_exception
    util.raise_(
  File "/home/airflow/.local/lib/python3.12/site-packages/sqlalchemy/util/compat.py", line 211, in raise_
    raise exception
  File "/home/airflow/.local/lib/python3.12/site-packages/sqlalchemy/engine/base.py", line 1890, in _execute_context
    self.dialect.do_executemany(
  File "/home/airflow/.local/lib/python3.12/site-packages/sqlalchemy/dialects/postgresql/psycopg2.py", line 982, in do_executemany
    context._psycopg2_fetched_rows = xtras.execute_values(
                                     ^^^^^^^^^^^^^^^^^^^^^
  File "/home/airflow/.local/lib/python3.12/site-packages/psycopg2/extras.py", line 1299, in execute_values
    cur.execute(b''.join(parts))
sqlalchemy.exc.ProgrammingError: (psycopg2.errors.UndefinedColumn) column "STOCK_ID" of relation "fact_table" does not exist
LINE 1: ...D_PRICE", "Total_Trades", "AVERAGE_TRADED_PRICE", "STOCK_ID"...
                                                             ^

[SQL: INSERT INTO fact_table ("SECURITY_ID", "BUSINESS_DATE", "TOTAL_TRADED_QUANTITY", "CLOSE_PRICE", "LAST_UPDATED_PRICE", "Total_Trades", "AVERAGE_TRADED_PRICE", "STOCK_ID") VALUES (%(SECURITY_ID)s, %(BUSINESS_DATE)s, %(TOTAL_TRADED_QUANTITY)s, %(CLOSE_PRICE)s, %(LAST_UPDATED_PRICE)s, %(Total_Trades)s, %(AVERAGE_TRADED_PRICE)s, %(STOCK_ID)s)]
[parameters: ({'SECURITY_ID': 'ADBL', 'BUSINESS_DATE': datetime.datetime(2024, 7, 9, 0, 0), 'TOTAL_TRADED_QUANTITY': 274360, 'CLOSE_PRICE': 285.2, 'LAST_UPDATED_PRICE': '285.20(4.7)', 'Total_Trades': 384, 'AVERAGE_TRADED_PRICE': 285.25, 'STOCK_ID': 'ADBL_2024-07-09'}, {'SECURITY_ID': 'AHL', 'BUSINESS_DATE': datetime.datetime(2024, 7, 9, 0, 0), 'TOTAL_TRADED_QUANTITY': 9636, 'CLOSE_PRICE': 521.3, 'LAST_UPDATED_PRICE': '521.30(4.3)', 'Total_Trades': 104, 'AVERAGE_TRADED_PRICE': 518.39, 'STOCK_ID': 'AHL_2024-07-09'}, {'SECURITY_ID': 'AHPC', 'BUSINESS_DATE': datetime.datetime(2024, 7, 9, 0, 0), 'TOTAL_TRADED_QUANTITY': 95155, 'CLOSE_PRICE': 154.8, 'LAST_UPDATED_PRICE': '154.80(-0.2)', 'Total_Trades': 310, 'AVERAGE_TRADED_PRICE': 154.33, 'STOCK_ID': 'AHPC_2024-07-09'}, {'SECURITY_ID': 'AKJCL', 'BUSINESS_DATE': datetime.datetime(2024, 7, 9, 0, 0), 'TOTAL_TRADED_QUANTITY': 74445, 'CLOSE_PRICE': 221.0, 'LAST_UPDATED_PRICE': '221.00(-3)', 'Total_Trades': 410, 'AVERAGE_TRADED_PRICE': 221.13, 'STOCK_ID': 'AKJCL_2024-07-09'}, {'SECURITY_ID': 'AKPL', 'BUSINESS_DATE': datetime.datetime(2024, 7, 9, 0, 0), 'TOTAL_TRADED_QUANTITY': 60264, 'CLOSE_PRICE': 164.0, 'LAST_UPDATED_PRICE': '164.00(1.5)', 'Total_Trades': 272, 'AVERAGE_TRADED_PRICE': 163.25, 'STOCK_ID': 'AKPL_2024-07-09'}, {'SECURITY_ID': 'ALBSL', 'BUSINESS_DATE': datetime.datetime(2024, 7, 9, 0, 0), 'TOTAL_TRADED_QUANTITY': 22930, 'CLOSE_PRICE': 1070.0, 'LAST_UPDATED_PRICE': '1,070.00(55.2)', 'Total_Trades': 380, 'AVERAGE_TRADED_PRICE': 1055.58, 'STOCK_ID': 'ALBSL_2024-07-09'}, {'SECURITY_ID': 'ALICL', 'BUSINESS_DATE': datetime.datetime(2024, 7, 9, 0, 0), 'TOTAL_TRADED_QUANTITY': 60948, 'CLOSE_PRICE': 590.0, 'LAST_UPDATED_PRICE': '590.00(-5)', 'Total_Trades': 244, 'AVERAGE_TRADED_PRICE': 586.92, 'STOCK_ID': 'ALICL_2024-07-09'}, {'SECURITY_ID': 'ANLB', 'BUSINESS_DATE': datetime.datetime(2024, 7, 9, 0, 0), 'TOTAL_TRADED_QUANTITY': 9114, 'CLOSE_PRICE': 2659.6, 'LAST_UPDATED_PRICE': '2,659.60(241.7)', 'Total_Trades': 365, 'AVERAGE_TRADED_PRICE': 2605.43, 'STOCK_ID': 'ANLB_2024-07-09'}  ... displaying 10 of 315 total bound parameter sets ...  {'SECURITY_ID': 'VLUCL', 'BUSINESS_DATE': datetime.datetime(2024, 7, 9, 0, 0), 'TOTAL_TRADED_QUANTITY': 13321, 'CLOSE_PRICE': 513.0, 'LAST_UPDATED_PRICE': '513.00(4.2)', 'Total_Trades': 248, 'AVERAGE_TRADED_PRICE': 511.52, 'STOCK_ID': 'VLUCL_2024-07-09'}, {'SECURITY_ID': 'WNLB', 'BUSINESS_DATE': datetime.datetime(2024, 7, 9, 0, 0), 'TOTAL_TRADED_QUANTITY': 4932, 'CLOSE_PRICE': 1522.0, 'LAST_UPDATED_PRICE': '1,522.00(73)', 'Total_Trades': 129, 'AVERAGE_TRADED_PRICE': 1511.85, 'STOCK_ID': 'WNLB_2024-07-09'})]
(Background on this error at: https://sqlalche.me/e/14/f405)
[2024-07-10T09:00:11.150+0000] {taskinstance.py:1206} INFO - Marking task as UP_FOR_RETRY. dag_id=market_etl, task_id=load_data_to_postgres, run_id=manual__2024-07-10T08:55:25.813716+00:00, execution_date=20240710T085525, start_date=20240710T090010, end_date=20240710T090011
[2024-07-10T09:00:11.162+0000] {standard_task_runner.py:110} ERROR - Failed to execute job 269 for task load_data_to_postgres ((psycopg2.errors.UndefinedColumn) column "STOCK_ID" of relation "fact_table" does not exist
LINE 1: ...D_PRICE", "Total_Trades", "AVERAGE_TRADED_PRICE", "STOCK_ID"...
                                                             ^

[SQL: INSERT INTO fact_table ("SECURITY_ID", "BUSINESS_DATE", "TOTAL_TRADED_QUANTITY", "CLOSE_PRICE", "LAST_UPDATED_PRICE", "Total_Trades", "AVERAGE_TRADED_PRICE", "STOCK_ID") VALUES (%(SECURITY_ID)s, %(BUSINESS_DATE)s, %(TOTAL_TRADED_QUANTITY)s, %(CLOSE_PRICE)s, %(LAST_UPDATED_PRICE)s, %(Total_Trades)s, %(AVERAGE_TRADED_PRICE)s, %(STOCK_ID)s)]
[parameters: ({'SECURITY_ID': 'ADBL', 'BUSINESS_DATE': datetime.datetime(2024, 7, 9, 0, 0), 'TOTAL_TRADED_QUANTITY': 274360, 'CLOSE_PRICE': 285.2, 'LAST_UPDATED_PRICE': '285.20(4.7)', 'Total_Trades': 384, 'AVERAGE_TRADED_PRICE': 285.25, 'STOCK_ID': 'ADBL_2024-07-09'}, {'SECURITY_ID': 'AHL', 'BUSINESS_DATE': datetime.datetime(2024, 7, 9, 0, 0), 'TOTAL_TRADED_QUANTITY': 9636, 'CLOSE_PRICE': 521.3, 'LAST_UPDATED_PRICE': '521.30(4.3)', 'Total_Trades': 104, 'AVERAGE_TRADED_PRICE': 518.39, 'STOCK_ID': 'AHL_2024-07-09'}, {'SECURITY_ID': 'AHPC', 'BUSINESS_DATE': datetime.datetime(2024, 7, 9, 0, 0), 'TOTAL_TRADED_QUANTITY': 95155, 'CLOSE_PRICE': 154.8, 'LAST_UPDATED_PRICE': '154.80(-0.2)', 'Total_Trades': 310, 'AVERAGE_TRADED_PRICE': 154.33, 'STOCK_ID': 'AHPC_2024-07-09'}, {'SECURITY_ID': 'AKJCL', 'BUSINESS_DATE': datetime.datetime(2024, 7, 9, 0, 0), 'TOTAL_TRADED_QUANTITY': 74445, 'CLOSE_PRICE': 221.0, 'LAST_UPDATED_PRICE': '221.00(-3)', 'Total_Trades': 410, 'AVERAGE_TRADED_PRICE': 221.13, 'STOCK_ID': 'AKJCL_2024-07-09'}, {'SECURITY_ID': 'AKPL', 'BUSINESS_DATE': datetime.datetime(2024, 7, 9, 0, 0), 'TOTAL_TRADED_QUANTITY': 60264, 'CLOSE_PRICE': 164.0, 'LAST_UPDATED_PRICE': '164.00(1.5)', 'Total_Trades': 272, 'AVERAGE_TRADED_PRICE': 163.25, 'STOCK_ID': 'AKPL_2024-07-09'}, {'SECURITY_ID': 'ALBSL', 'BUSINESS_DATE': datetime.datetime(2024, 7, 9, 0, 0), 'TOTAL_TRADED_QUANTITY': 22930, 'CLOSE_PRICE': 1070.0, 'LAST_UPDATED_PRICE': '1,070.00(55.2)', 'Total_Trades': 380, 'AVERAGE_TRADED_PRICE': 1055.58, 'STOCK_ID': 'ALBSL_2024-07-09'}, {'SECURITY_ID': 'ALICL', 'BUSINESS_DATE': datetime.datetime(2024, 7, 9, 0, 0), 'TOTAL_TRADED_QUANTITY': 60948, 'CLOSE_PRICE': 590.0, 'LAST_UPDATED_PRICE': '590.00(-5)', 'Total_Trades': 244, 'AVERAGE_TRADED_PRICE': 586.92, 'STOCK_ID': 'ALICL_2024-07-09'}, {'SECURITY_ID': 'ANLB', 'BUSINESS_DATE': datetime.datetime(2024, 7, 9, 0, 0), 'TOTAL_TRADED_QUANTITY': 9114, 'CLOSE_PRICE': 2659.6, 'LAST_UPDATED_PRICE': '2,659.60(241.7)', 'Total_Trades': 365, 'AVERAGE_TRADED_PRICE': 2605.43, 'STOCK_ID': 'ANLB_2024-07-09'}  ... displaying 10 of 315 total bound parameter sets ...  {'SECURITY_ID': 'VLUCL', 'BUSINESS_DATE': datetime.datetime(2024, 7, 9, 0, 0), 'TOTAL_TRADED_QUANTITY': 13321, 'CLOSE_PRICE': 513.0, 'LAST_UPDATED_PRICE': '513.00(4.2)', 'Total_Trades': 248, 'AVERAGE_TRADED_PRICE': 511.52, 'STOCK_ID': 'VLUCL_2024-07-09'}, {'SECURITY_ID': 'WNLB', 'BUSINESS_DATE': datetime.datetime(2024, 7, 9, 0, 0), 'TOTAL_TRADED_QUANTITY': 4932, 'CLOSE_PRICE': 1522.0, 'LAST_UPDATED_PRICE': '1,522.00(73)', 'Total_Trades': 129, 'AVERAGE_TRADED_PRICE': 1511.85, 'STOCK_ID': 'WNLB_2024-07-09'})]
(Background on this error at: https://sqlalche.me/e/14/f405); 136)
[2024-07-10T09:00:11.191+0000] {local_task_job_runner.py:240} INFO - Task exited with return code 1
[2024-07-10T09:00:11.228+0000] {taskinstance.py:3503} INFO - 0 downstream tasks scheduled from follow-on schedule check
[2024-07-10T09:00:11.229+0000] {local_task_job_runner.py:222} INFO - ::endgroup::
