[2024-07-01T05:13:42.446+0000] {local_task_job_runner.py:120} INFO - ::group::Pre task execution logs
[2024-07-01T05:13:42.492+0000] {taskinstance.py:2076} INFO - Dependencies all met for dep_context=non-requeueable deps ti=<TaskInstance: market_etl.load_market_data manual__2024-07-01T05:13:37.231157+00:00 [queued]>
[2024-07-01T05:13:42.504+0000] {taskinstance.py:2076} INFO - Dependencies all met for dep_context=requeueable deps ti=<TaskInstance: market_etl.load_market_data manual__2024-07-01T05:13:37.231157+00:00 [queued]>
[2024-07-01T05:13:42.504+0000] {taskinstance.py:2306} INFO - Starting attempt 1 of 4
[2024-07-01T05:13:42.518+0000] {taskinstance.py:2330} INFO - Executing <Task(_PythonDecoratedOperator): load_market_data> on 2024-07-01 05:13:37.231157+00:00
[2024-07-01T05:13:42.528+0000] {warnings.py:112} WARNING - /home/airflow/.local/lib/python3.12/site-packages/airflow/task/task_runner/standard_task_runner.py:61: DeprecationWarning: This process (pid=54) is multi-threaded, use of fork() may lead to deadlocks in the child.
  pid = os.fork()

[2024-07-01T05:13:42.529+0000] {standard_task_runner.py:63} INFO - Started process 56 to run task
[2024-07-01T05:13:42.529+0000] {standard_task_runner.py:90} INFO - Running: ['airflow', 'tasks', 'run', 'market_etl', 'load_market_data', 'manual__2024-07-01T05:13:37.231157+00:00', '--job-id', '349', '--raw', '--subdir', 'DAGS_FOLDER/etl.py', '--cfg-path', '/tmp/tmph9an7_2o']
[2024-07-01T05:13:42.531+0000] {standard_task_runner.py:91} INFO - Job 349: Subtask load_market_data
[2024-07-01T05:13:42.585+0000] {task_command.py:426} INFO - Running <TaskInstance: market_etl.load_market_data manual__2024-07-01T05:13:37.231157+00:00 [running]> on host 5eec0a067191
[2024-07-01T05:13:42.798+0000] {taskinstance.py:2648} INFO - Exporting env vars: AIRFLOW_CTX_DAG_OWNER='airflow' AIRFLOW_CTX_DAG_ID='market_etl' AIRFLOW_CTX_TASK_ID='load_market_data' AIRFLOW_CTX_EXECUTION_DATE='2024-07-01T05:13:37.231157+00:00' AIRFLOW_CTX_TRY_NUMBER='1' AIRFLOW_CTX_DAG_RUN_ID='manual__2024-07-01T05:13:37.231157+00:00'
[2024-07-01T05:13:42.799+0000] {taskinstance.py:430} INFO - ::endgroup::
[2024-07-01T05:13:42.831+0000] {base.py:84} INFO - Using connection ID 'market_database_conn' for task execution.
[2024-07-01T05:13:42.912+0000] {taskinstance.py:441} INFO - ::group::Post task execution logs
[2024-07-01T05:13:42.913+0000] {taskinstance.py:2905} ERROR - Task failed with exception
Traceback (most recent call last):
  File "/home/airflow/.local/lib/python3.12/site-packages/sqlalchemy/engine/base.py", line 1890, in _execute_context
    self.dialect.do_executemany(
  File "/home/airflow/.local/lib/python3.12/site-packages/sqlalchemy/dialects/postgresql/psycopg2.py", line 982, in do_executemany
    context._psycopg2_fetched_rows = xtras.execute_values(
                                     ^^^^^^^^^^^^^^^^^^^^^
  File "/home/airflow/.local/lib/python3.12/site-packages/psycopg2/extras.py", line 1299, in execute_values
    cur.execute(b''.join(parts))
psycopg2.errors.UndefinedColumn: column "Sn" of relation "nepse_market_data" does not exist
LINE 1: INSERT INTO nepse_market_data ("Sn", "Symbol", "Close_Price_...
                                       ^


The above exception was the direct cause of the following exception:

Traceback (most recent call last):
  File "/home/airflow/.local/lib/python3.12/site-packages/airflow/models/taskinstance.py", line 465, in _execute_task
    result = _execute_callable(context=context, **execute_callable_kwargs)
             ^^^^^^^^^^^^^^^^^^^^^^^^^^^^^^^^^^^^^^^^^^^^^^^^^^^^^^^^^^^^^
  File "/home/airflow/.local/lib/python3.12/site-packages/airflow/models/taskinstance.py", line 432, in _execute_callable
    return execute_callable(context=context, **execute_callable_kwargs)
           ^^^^^^^^^^^^^^^^^^^^^^^^^^^^^^^^^^^^^^^^^^^^^^^^^^^^^^^^^^^^
  File "/home/airflow/.local/lib/python3.12/site-packages/airflow/models/baseoperator.py", line 401, in wrapper
    return func(self, *args, **kwargs)
           ^^^^^^^^^^^^^^^^^^^^^^^^^^^
  File "/home/airflow/.local/lib/python3.12/site-packages/airflow/decorators/base.py", line 265, in execute
    return_value = super().execute(context)
                   ^^^^^^^^^^^^^^^^^^^^^^^^
  File "/home/airflow/.local/lib/python3.12/site-packages/airflow/models/baseoperator.py", line 401, in wrapper
    return func(self, *args, **kwargs)
           ^^^^^^^^^^^^^^^^^^^^^^^^^^^
  File "/home/airflow/.local/lib/python3.12/site-packages/airflow/operators/python.py", line 235, in execute
    return_value = self.execute_callable()
                   ^^^^^^^^^^^^^^^^^^^^^^^
  File "/home/airflow/.local/lib/python3.12/site-packages/airflow/operators/python.py", line 252, in execute_callable
    return self.python_callable(*self.op_args, **self.op_kwargs)
           ^^^^^^^^^^^^^^^^^^^^^^^^^^^^^^^^^^^^^^^^^^^^^^^^^^^^^
  File "/opt/airflow/dags/etl.py", line 56, in load_market_data
    flattened_dataframe.to_sql(
  File "/home/airflow/.local/lib/python3.12/site-packages/pandas/util/_decorators.py", line 333, in wrapper
    return func(*args, **kwargs)
           ^^^^^^^^^^^^^^^^^^^^^
  File "/home/airflow/.local/lib/python3.12/site-packages/pandas/core/generic.py", line 3008, in to_sql
    return sql.to_sql(
           ^^^^^^^^^^^
  File "/home/airflow/.local/lib/python3.12/site-packages/pandas/io/sql.py", line 788, in to_sql
    return pandas_sql.to_sql(
           ^^^^^^^^^^^^^^^^^^
  File "/home/airflow/.local/lib/python3.12/site-packages/pandas/io/sql.py", line 1958, in to_sql
    total_inserted = sql_engine.insert_records(
                     ^^^^^^^^^^^^^^^^^^^^^^^^^^
  File "/home/airflow/.local/lib/python3.12/site-packages/pandas/io/sql.py", line 1507, in insert_records
    raise err
  File "/home/airflow/.local/lib/python3.12/site-packages/pandas/io/sql.py", line 1498, in insert_records
    return table.insert(chunksize=chunksize, method=method)
           ^^^^^^^^^^^^^^^^^^^^^^^^^^^^^^^^^^^^^^^^^^^^^^^^
  File "/home/airflow/.local/lib/python3.12/site-packages/pandas/io/sql.py", line 1059, in insert
    num_inserted = exec_insert(conn, keys, chunk_iter)
                   ^^^^^^^^^^^^^^^^^^^^^^^^^^^^^^^^^^^
  File "/home/airflow/.local/lib/python3.12/site-packages/pandas/io/sql.py", line 951, in _execute_insert
    result = conn.execute(self.table.insert(), data)
             ^^^^^^^^^^^^^^^^^^^^^^^^^^^^^^^^^^^^^^^
  File "/home/airflow/.local/lib/python3.12/site-packages/sqlalchemy/engine/base.py", line 1385, in execute
    return meth(self, multiparams, params, _EMPTY_EXECUTION_OPTS)
           ^^^^^^^^^^^^^^^^^^^^^^^^^^^^^^^^^^^^^^^^^^^^^^^^^^^^^^
  File "/home/airflow/.local/lib/python3.12/site-packages/sqlalchemy/sql/elements.py", line 334, in _execute_on_connection
    return connection._execute_clauseelement(
           ^^^^^^^^^^^^^^^^^^^^^^^^^^^^^^^^^^
  File "/home/airflow/.local/lib/python3.12/site-packages/sqlalchemy/engine/base.py", line 1577, in _execute_clauseelement
    ret = self._execute_context(
          ^^^^^^^^^^^^^^^^^^^^^^
  File "/home/airflow/.local/lib/python3.12/site-packages/sqlalchemy/engine/base.py", line 1953, in _execute_context
    self._handle_dbapi_exception(
  File "/home/airflow/.local/lib/python3.12/site-packages/sqlalchemy/engine/base.py", line 2134, in _handle_dbapi_exception
    util.raise_(
  File "/home/airflow/.local/lib/python3.12/site-packages/sqlalchemy/util/compat.py", line 211, in raise_
    raise exception
  File "/home/airflow/.local/lib/python3.12/site-packages/sqlalchemy/engine/base.py", line 1890, in _execute_context
    self.dialect.do_executemany(
  File "/home/airflow/.local/lib/python3.12/site-packages/sqlalchemy/dialects/postgresql/psycopg2.py", line 982, in do_executemany
    context._psycopg2_fetched_rows = xtras.execute_values(
                                     ^^^^^^^^^^^^^^^^^^^^^
  File "/home/airflow/.local/lib/python3.12/site-packages/psycopg2/extras.py", line 1299, in execute_values
    cur.execute(b''.join(parts))
sqlalchemy.exc.ProgrammingError: (psycopg2.errors.UndefinedColumn) column "Sn" of relation "nepse_market_data" does not exist
LINE 1: INSERT INTO nepse_market_data ("Sn", "Symbol", "Close_Price_...
                                       ^

[SQL: INSERT INTO nepse_market_data ("Sn", "Symbol", "Close_Price_Rs", "Open_Price_Rs", "High_Price_Rs", "Low_Price_Rs", "Total_Traded_Quantity", "Total_Traded_Value", "Total_Trades", "LTP", "Previous_Day_Close_Price_Rs", "Average_Traded_Price_Rs", "Fifty_Two_Week_High_Rs", "Fifty_Two_Week_Low_Rs", "Market_Capitalization_Rs__Amt_in_Millions", "Close_Date") VALUES (%(Sn)s, %(Symbol)s, %(Close_Price_Rs)s, %(Open_Price_Rs)s, %(High_Price_Rs)s, %(Low_Price_Rs)s, %(Total_Traded_Quantity)s, %(Total_Traded_Value)s, %(Total_Trades)s, %(LTP)s, %(Previous_Day_Close_Price_Rs)s, %(Average_Traded_Price_Rs)s, %(Fifty_Two_Week_High_Rs)s, %(Fifty_Two_Week_Low_Rs)s, %(Market_Capitalization_Rs__Amt_in_Millions)s, %(Close_Date)s)]
[parameters: ({'Sn': 2, 'Symbol': 'KQ', 'Close_Price_Rs': 1.0, 'Open_Price_Rs': 1.0, 'High_Price_Rs': 1.0, 'Low_Price_Rs': 1.0, 'Total_Traded_Quantity': 1, 'Total_Traded_Value': 1.0, 'Total_Trades': 1, 'LTP': '1', 'Previous_Day_Close_Price_Rs': 1.0, 'Average_Traded_Price_Rs': 1.0, 'Fifty_Two_Week_High_Rs': 1.0, 'Fifty_Two_Week_Low_Rs': 1.0, 'Market_Capitalization_Rs__Amt_in_Millions': 1.0, 'Close_Date': datetime.datetime(2024, 6, 30, 0, 0)}, {'Sn': 3, 'Symbol': 'KQ', 'Close_Price_Rs': 1.0, 'Open_Price_Rs': 1.0, 'High_Price_Rs': 1.0, 'Low_Price_Rs': 1.0, 'Total_Traded_Quantity': 1, 'Total_Traded_Value': 1.0, 'Total_Trades': 1, 'LTP': '1', 'Previous_Day_Close_Price_Rs': 1.0, 'Average_Traded_Price_Rs': 1.0, 'Fifty_Two_Week_High_Rs': 1.0, 'Fifty_Two_Week_Low_Rs': 1.0, 'Market_Capitalization_Rs__Amt_in_Millions': 1.0, 'Close_Date': datetime.datetime(2024, 6, 30, 0, 0)})]
(Background on this error at: https://sqlalche.me/e/14/f405)
[2024-07-01T05:13:42.950+0000] {taskinstance.py:1206} INFO - Marking task as UP_FOR_RETRY. dag_id=market_etl, task_id=load_market_data, run_id=manual__2024-07-01T05:13:37.231157+00:00, execution_date=20240701T051337, start_date=20240701T051342, end_date=20240701T051342
[2024-07-01T05:13:42.963+0000] {standard_task_runner.py:110} ERROR - Failed to execute job 349 for task load_market_data ((psycopg2.errors.UndefinedColumn) column "Sn" of relation "nepse_market_data" does not exist
LINE 1: INSERT INTO nepse_market_data ("Sn", "Symbol", "Close_Price_...
                                       ^

[SQL: INSERT INTO nepse_market_data ("Sn", "Symbol", "Close_Price_Rs", "Open_Price_Rs", "High_Price_Rs", "Low_Price_Rs", "Total_Traded_Quantity", "Total_Traded_Value", "Total_Trades", "LTP", "Previous_Day_Close_Price_Rs", "Average_Traded_Price_Rs", "Fifty_Two_Week_High_Rs", "Fifty_Two_Week_Low_Rs", "Market_Capitalization_Rs__Amt_in_Millions", "Close_Date") VALUES (%(Sn)s, %(Symbol)s, %(Close_Price_Rs)s, %(Open_Price_Rs)s, %(High_Price_Rs)s, %(Low_Price_Rs)s, %(Total_Traded_Quantity)s, %(Total_Traded_Value)s, %(Total_Trades)s, %(LTP)s, %(Previous_Day_Close_Price_Rs)s, %(Average_Traded_Price_Rs)s, %(Fifty_Two_Week_High_Rs)s, %(Fifty_Two_Week_Low_Rs)s, %(Market_Capitalization_Rs__Amt_in_Millions)s, %(Close_Date)s)]
[parameters: ({'Sn': 2, 'Symbol': 'KQ', 'Close_Price_Rs': 1.0, 'Open_Price_Rs': 1.0, 'High_Price_Rs': 1.0, 'Low_Price_Rs': 1.0, 'Total_Traded_Quantity': 1, 'Total_Traded_Value': 1.0, 'Total_Trades': 1, 'LTP': '1', 'Previous_Day_Close_Price_Rs': 1.0, 'Average_Traded_Price_Rs': 1.0, 'Fifty_Two_Week_High_Rs': 1.0, 'Fifty_Two_Week_Low_Rs': 1.0, 'Market_Capitalization_Rs__Amt_in_Millions': 1.0, 'Close_Date': datetime.datetime(2024, 6, 30, 0, 0)}, {'Sn': 3, 'Symbol': 'KQ', 'Close_Price_Rs': 1.0, 'Open_Price_Rs': 1.0, 'High_Price_Rs': 1.0, 'Low_Price_Rs': 1.0, 'Total_Traded_Quantity': 1, 'Total_Traded_Value': 1.0, 'Total_Trades': 1, 'LTP': '1', 'Previous_Day_Close_Price_Rs': 1.0, 'Average_Traded_Price_Rs': 1.0, 'Fifty_Two_Week_High_Rs': 1.0, 'Fifty_Two_Week_Low_Rs': 1.0, 'Market_Capitalization_Rs__Amt_in_Millions': 1.0, 'Close_Date': datetime.datetime(2024, 6, 30, 0, 0)})]
(Background on this error at: https://sqlalche.me/e/14/f405); 56)
[2024-07-01T05:13:43.009+0000] {local_task_job_runner.py:240} INFO - Task exited with return code 1
[2024-07-01T05:13:43.030+0000] {taskinstance.py:3503} INFO - 0 downstream tasks scheduled from follow-on schedule check
[2024-07-01T05:13:43.031+0000] {local_task_job_runner.py:222} INFO - ::endgroup::
