[2024-06-25T10:05:54.810+0000] {local_task_job_runner.py:120} INFO - ::group::Pre task execution logs
[2024-06-25T10:05:54.825+0000] {taskinstance.py:2076} INFO - Dependencies all met for dep_context=non-requeueable deps ti=<TaskInstance: market_etl.load_market_data manual__2024-06-25T10:05:30.458824+00:00 [queued]>
[2024-06-25T10:05:54.830+0000] {taskinstance.py:2076} INFO - Dependencies all met for dep_context=requeueable deps ti=<TaskInstance: market_etl.load_market_data manual__2024-06-25T10:05:30.458824+00:00 [queued]>
[2024-06-25T10:05:54.830+0000] {taskinstance.py:2306} INFO - Starting attempt 1 of 4
[2024-06-25T10:05:54.837+0000] {taskinstance.py:2330} INFO - Executing <Task(_PythonDecoratedOperator): load_market_data> on 2024-06-25 10:05:30.458824+00:00
[2024-06-25T10:05:54.839+0000] {warnings.py:112} WARNING - /home/airflow/.local/lib/python3.12/site-packages/airflow/task/task_runner/standard_task_runner.py:61: DeprecationWarning: This process (pid=61) is multi-threaded, use of fork() may lead to deadlocks in the child.
  pid = os.fork()

[2024-06-25T10:05:54.840+0000] {standard_task_runner.py:63} INFO - Started process 63 to run task
[2024-06-25T10:05:54.841+0000] {standard_task_runner.py:90} INFO - Running: ['airflow', 'tasks', 'run', 'market_etl', 'load_market_data', 'manual__2024-06-25T10:05:30.458824+00:00', '--job-id', '38', '--raw', '--subdir', 'DAGS_FOLDER/etl.py', '--cfg-path', '/tmp/tmphpfs7gm_']
[2024-06-25T10:05:54.842+0000] {standard_task_runner.py:91} INFO - Job 38: Subtask load_market_data
[2024-06-25T10:05:54.879+0000] {task_command.py:426} INFO - Running <TaskInstance: market_etl.load_market_data manual__2024-06-25T10:05:30.458824+00:00 [running]> on host f3f48f0457b9
[2024-06-25T10:05:55.021+0000] {taskinstance.py:2648} INFO - Exporting env vars: AIRFLOW_CTX_DAG_OWNER='airflow' AIRFLOW_CTX_DAG_ID='market_etl' AIRFLOW_CTX_TASK_ID='load_market_data' AIRFLOW_CTX_EXECUTION_DATE='2024-06-25T10:05:30.458824+00:00' AIRFLOW_CTX_TRY_NUMBER='1' AIRFLOW_CTX_DAG_RUN_ID='manual__2024-06-25T10:05:30.458824+00:00'
[2024-06-25T10:05:55.022+0000] {taskinstance.py:430} INFO - ::endgroup::
[2024-06-25T10:05:55.030+0000] {base.py:84} INFO - Using connection ID 'market_database_conn' for task execution.
[2024-06-25T10:05:55.052+0000] {taskinstance.py:441} INFO - ::group::Post task execution logs
[2024-06-25T10:05:55.052+0000] {taskinstance.py:2905} ERROR - Task failed with exception
Traceback (most recent call last):
  File "/home/airflow/.local/lib/python3.12/site-packages/sqlalchemy/engine/base.py", line 1890, in _execute_context
    self.dialect.do_executemany(
  File "/home/airflow/.local/lib/python3.12/site-packages/sqlalchemy/dialects/postgresql/psycopg2.py", line 982, in do_executemany
    context._psycopg2_fetched_rows = xtras.execute_values(
                                     ^^^^^^^^^^^^^^^^^^^^^
  File "/home/airflow/.local/lib/python3.12/site-packages/psycopg2/extras.py", line 1299, in execute_values
    cur.execute(b''.join(parts))
psycopg2.errors.UndefinedColumn: column "timestamp" of relation "market_data" does not exist
LINE 1: ... market_data (volume, vw, open, close, high, low, timestamp,...
                                                             ^


The above exception was the direct cause of the following exception:

Traceback (most recent call last):
  File "/home/airflow/.local/lib/python3.12/site-packages/airflow/models/taskinstance.py", line 465, in _execute_task
    result = _execute_callable(context=context, **execute_callable_kwargs)
             ^^^^^^^^^^^^^^^^^^^^^^^^^^^^^^^^^^^^^^^^^^^^^^^^^^^^^^^^^^^^^
  File "/home/airflow/.local/lib/python3.12/site-packages/airflow/models/taskinstance.py", line 432, in _execute_callable
    return execute_callable(context=context, **execute_callable_kwargs)
           ^^^^^^^^^^^^^^^^^^^^^^^^^^^^^^^^^^^^^^^^^^^^^^^^^^^^^^^^^^^^
  File "/home/airflow/.local/lib/python3.12/site-packages/airflow/models/baseoperator.py", line 401, in wrapper
    return func(self, *args, **kwargs)
           ^^^^^^^^^^^^^^^^^^^^^^^^^^^
  File "/home/airflow/.local/lib/python3.12/site-packages/airflow/decorators/base.py", line 265, in execute
    return_value = super().execute(context)
                   ^^^^^^^^^^^^^^^^^^^^^^^^
  File "/home/airflow/.local/lib/python3.12/site-packages/airflow/models/baseoperator.py", line 401, in wrapper
    return func(self, *args, **kwargs)
           ^^^^^^^^^^^^^^^^^^^^^^^^^^^
  File "/home/airflow/.local/lib/python3.12/site-packages/airflow/operators/python.py", line 235, in execute
    return_value = self.execute_callable()
                   ^^^^^^^^^^^^^^^^^^^^^^^
  File "/home/airflow/.local/lib/python3.12/site-packages/airflow/operators/python.py", line 252, in execute_callable
    return self.python_callable(*self.op_args, **self.op_kwargs)
           ^^^^^^^^^^^^^^^^^^^^^^^^^^^^^^^^^^^^^^^^^^^^^^^^^^^^^
  File "/opt/airflow/dags/etl.py", line 72, in load_market_data
    flattened_dataframe.to_sql(
  File "/home/airflow/.local/lib/python3.12/site-packages/pandas/util/_decorators.py", line 333, in wrapper
    return func(*args, **kwargs)
           ^^^^^^^^^^^^^^^^^^^^^
  File "/home/airflow/.local/lib/python3.12/site-packages/pandas/core/generic.py", line 3008, in to_sql
    return sql.to_sql(
           ^^^^^^^^^^^
  File "/home/airflow/.local/lib/python3.12/site-packages/pandas/io/sql.py", line 788, in to_sql
    return pandas_sql.to_sql(
           ^^^^^^^^^^^^^^^^^^
  File "/home/airflow/.local/lib/python3.12/site-packages/pandas/io/sql.py", line 1958, in to_sql
    total_inserted = sql_engine.insert_records(
                     ^^^^^^^^^^^^^^^^^^^^^^^^^^
  File "/home/airflow/.local/lib/python3.12/site-packages/pandas/io/sql.py", line 1507, in insert_records
    raise err
  File "/home/airflow/.local/lib/python3.12/site-packages/pandas/io/sql.py", line 1498, in insert_records
    return table.insert(chunksize=chunksize, method=method)
           ^^^^^^^^^^^^^^^^^^^^^^^^^^^^^^^^^^^^^^^^^^^^^^^^
  File "/home/airflow/.local/lib/python3.12/site-packages/pandas/io/sql.py", line 1059, in insert
    num_inserted = exec_insert(conn, keys, chunk_iter)
                   ^^^^^^^^^^^^^^^^^^^^^^^^^^^^^^^^^^^
  File "/home/airflow/.local/lib/python3.12/site-packages/pandas/io/sql.py", line 951, in _execute_insert
    result = conn.execute(self.table.insert(), data)
             ^^^^^^^^^^^^^^^^^^^^^^^^^^^^^^^^^^^^^^^
  File "/home/airflow/.local/lib/python3.12/site-packages/sqlalchemy/engine/base.py", line 1385, in execute
    return meth(self, multiparams, params, _EMPTY_EXECUTION_OPTS)
           ^^^^^^^^^^^^^^^^^^^^^^^^^^^^^^^^^^^^^^^^^^^^^^^^^^^^^^
  File "/home/airflow/.local/lib/python3.12/site-packages/sqlalchemy/sql/elements.py", line 334, in _execute_on_connection
    return connection._execute_clauseelement(
           ^^^^^^^^^^^^^^^^^^^^^^^^^^^^^^^^^^
  File "/home/airflow/.local/lib/python3.12/site-packages/sqlalchemy/engine/base.py", line 1577, in _execute_clauseelement
    ret = self._execute_context(
          ^^^^^^^^^^^^^^^^^^^^^^
  File "/home/airflow/.local/lib/python3.12/site-packages/sqlalchemy/engine/base.py", line 1953, in _execute_context
    self._handle_dbapi_exception(
  File "/home/airflow/.local/lib/python3.12/site-packages/sqlalchemy/engine/base.py", line 2134, in _handle_dbapi_exception
    util.raise_(
  File "/home/airflow/.local/lib/python3.12/site-packages/sqlalchemy/util/compat.py", line 211, in raise_
    raise exception
  File "/home/airflow/.local/lib/python3.12/site-packages/sqlalchemy/engine/base.py", line 1890, in _execute_context
    self.dialect.do_executemany(
  File "/home/airflow/.local/lib/python3.12/site-packages/sqlalchemy/dialects/postgresql/psycopg2.py", line 982, in do_executemany
    context._psycopg2_fetched_rows = xtras.execute_values(
                                     ^^^^^^^^^^^^^^^^^^^^^
  File "/home/airflow/.local/lib/python3.12/site-packages/psycopg2/extras.py", line 1299, in execute_values
    cur.execute(b''.join(parts))
sqlalchemy.exc.ProgrammingError: (psycopg2.errors.UndefinedColumn) column "timestamp" of relation "market_data" does not exist
LINE 1: ... market_data (volume, vw, open, close, high, low, timestamp,...
                                                             ^

[SQL: INSERT INTO market_data (volume, vw, open, close, high, low, timestamp, n, symbol) VALUES (%(volume)s, %(vw)s, %(open)s, %(close)s, %(high)s, %(low)s, %(timestamp)s, %(n)s, %(symbol)s)]
[parameters: ({'volume': 47314924.0, 'vw': 149.8529, 'open': 151.54, 'close': 149.93, 'high': 152.38, 'low': 148.39, 'timestamp': datetime.datetime(2024, 1, 2, 5, 0), 'n': 476432, 'symbol': 'AMZN'}, {'volume': 49410095.0, 'vw': 149.4055, 'open': 149.2, 'close': 148.47, 'high': 151.05, 'low': 148.33, 'timestamp': datetime.datetime(2024, 1, 3, 5, 0), 'n': 416954, 'symbol': 'AMZN'}, {'volume': 56039807.0, 'vw': 145.416, 'open': 145.59, 'close': 144.57, 'high': 147.38, 'low': 144.05, 'timestamp': datetime.datetime(2024, 1, 4, 5, 0), 'n': 541342, 'symbol': 'AMZN'}, {'volume': 45003147.0, 'vw': 145.4485, 'open': 144.69, 'close': 145.24, 'high': 146.59, 'low': 144.53, 'timestamp': datetime.datetime(2024, 1, 5, 5, 0), 'n': 380385, 'symbol': 'AMZN'}, {'volume': 46757053.0, 'vw': 148.3238, 'open': 146.74, 'close': 149.1, 'high': 149.4, 'low': 146.15, 'timestamp': datetime.datetime(2024, 1, 8, 5, 0), 'n': 410733, 'symbol': 'AMZN'}, {'volume': 43812567.0, 'vw': 150.6311, 'open': 148.33, 'close': 151.37, 'high': 151.71, 'low': 148.21, 'timestamp': datetime.datetime(2024, 1, 9, 5, 0), 'n': 403026, 'symbol': 'AMZN'}, {'volume': 44421830.0, 'vw': 153.4523, 'open': 152.06, 'close': 153.73, 'high': 154.42, 'low': 151.881, 'timestamp': datetime.datetime(2024, 1, 10, 5, 0), 'n': 430517, 'symbol': 'AMZN'}, {'volume': 49072691.0, 'vw': 155.0181, 'open': 155.04, 'close': 155.18, 'high': 157.17, 'low': 153.12, 'timestamp': datetime.datetime(2024, 1, 11, 5, 0), 'n': 468131, 'symbol': 'AMZN'}  ... displaying 10 of 120 total bound parameter sets ...  {'volume': 66858255.0, 'vw': 188.0574, 'open': 187.8, 'close': 189.08, 'high': 189.275, 'low': 185.86, 'timestamp': datetime.datetime(2024, 6, 21, 4, 0), 'n': 435715, 'symbol': 'AMZN'}, {'volume': 48143614.0, 'vw': 187.3312, 'open': 189.33, 'close': 185.57, 'high': 191.0, 'low': 185.33, 'timestamp': datetime.datetime(2024, 6, 24, 4, 0), 'n': 535288, 'symbol': 'AMZN'})]
(Background on this error at: https://sqlalche.me/e/14/f405)
[2024-06-25T10:05:55.069+0000] {taskinstance.py:1206} INFO - Marking task as UP_FOR_RETRY. dag_id=market_etl, task_id=load_market_data, run_id=manual__2024-06-25T10:05:30.458824+00:00, execution_date=20240625T100530, start_date=20240625T100554, end_date=20240625T100555
[2024-06-25T10:05:55.079+0000] {standard_task_runner.py:110} ERROR - Failed to execute job 38 for task load_market_data ((psycopg2.errors.UndefinedColumn) column "timestamp" of relation "market_data" does not exist
LINE 1: ... market_data (volume, vw, open, close, high, low, timestamp,...
                                                             ^

[SQL: INSERT INTO market_data (volume, vw, open, close, high, low, timestamp, n, symbol) VALUES (%(volume)s, %(vw)s, %(open)s, %(close)s, %(high)s, %(low)s, %(timestamp)s, %(n)s, %(symbol)s)]
[parameters: ({'volume': 47314924.0, 'vw': 149.8529, 'open': 151.54, 'close': 149.93, 'high': 152.38, 'low': 148.39, 'timestamp': datetime.datetime(2024, 1, 2, 5, 0), 'n': 476432, 'symbol': 'AMZN'}, {'volume': 49410095.0, 'vw': 149.4055, 'open': 149.2, 'close': 148.47, 'high': 151.05, 'low': 148.33, 'timestamp': datetime.datetime(2024, 1, 3, 5, 0), 'n': 416954, 'symbol': 'AMZN'}, {'volume': 56039807.0, 'vw': 145.416, 'open': 145.59, 'close': 144.57, 'high': 147.38, 'low': 144.05, 'timestamp': datetime.datetime(2024, 1, 4, 5, 0), 'n': 541342, 'symbol': 'AMZN'}, {'volume': 45003147.0, 'vw': 145.4485, 'open': 144.69, 'close': 145.24, 'high': 146.59, 'low': 144.53, 'timestamp': datetime.datetime(2024, 1, 5, 5, 0), 'n': 380385, 'symbol': 'AMZN'}, {'volume': 46757053.0, 'vw': 148.3238, 'open': 146.74, 'close': 149.1, 'high': 149.4, 'low': 146.15, 'timestamp': datetime.datetime(2024, 1, 8, 5, 0), 'n': 410733, 'symbol': 'AMZN'}, {'volume': 43812567.0, 'vw': 150.6311, 'open': 148.33, 'close': 151.37, 'high': 151.71, 'low': 148.21, 'timestamp': datetime.datetime(2024, 1, 9, 5, 0), 'n': 403026, 'symbol': 'AMZN'}, {'volume': 44421830.0, 'vw': 153.4523, 'open': 152.06, 'close': 153.73, 'high': 154.42, 'low': 151.881, 'timestamp': datetime.datetime(2024, 1, 10, 5, 0), 'n': 430517, 'symbol': 'AMZN'}, {'volume': 49072691.0, 'vw': 155.0181, 'open': 155.04, 'close': 155.18, 'high': 157.17, 'low': 153.12, 'timestamp': datetime.datetime(2024, 1, 11, 5, 0), 'n': 468131, 'symbol': 'AMZN'}  ... displaying 10 of 120 total bound parameter sets ...  {'volume': 66858255.0, 'vw': 188.0574, 'open': 187.8, 'close': 189.08, 'high': 189.275, 'low': 185.86, 'timestamp': datetime.datetime(2024, 6, 21, 4, 0), 'n': 435715, 'symbol': 'AMZN'}, {'volume': 48143614.0, 'vw': 187.3312, 'open': 189.33, 'close': 185.57, 'high': 191.0, 'low': 185.33, 'timestamp': datetime.datetime(2024, 6, 24, 4, 0), 'n': 535288, 'symbol': 'AMZN'})]
(Background on this error at: https://sqlalche.me/e/14/f405); 63)
[2024-06-25T10:05:55.102+0000] {local_task_job_runner.py:240} INFO - Task exited with return code 1
[2024-06-25T10:05:55.119+0000] {taskinstance.py:3503} INFO - 0 downstream tasks scheduled from follow-on schedule check
[2024-06-25T10:05:55.120+0000] {local_task_job_runner.py:222} INFO - ::endgroup::
