[2024-07-11T07:26:40.082+0000] {local_task_job_runner.py:120} INFO - ::group::Pre task execution logs
[2024-07-11T07:26:40.115+0000] {taskinstance.py:2076} INFO - Dependencies all met for dep_context=non-requeueable deps ti=<TaskInstance: market_etl.upload_to_s3__2 manual__2024-07-11T07:10:19.817387+00:00 [queued]>
[2024-07-11T07:26:40.124+0000] {taskinstance.py:2076} INFO - Dependencies all met for dep_context=requeueable deps ti=<TaskInstance: market_etl.upload_to_s3__2 manual__2024-07-11T07:10:19.817387+00:00 [queued]>
[2024-07-11T07:26:40.125+0000] {taskinstance.py:2306} INFO - Starting attempt 1 of 4
[2024-07-11T07:26:40.139+0000] {taskinstance.py:2330} INFO - Executing <Task(_PythonDecoratedOperator): upload_to_s3__2> on 2024-07-11 07:10:19.817387+00:00
[2024-07-11T07:26:40.146+0000] {warnings.py:112} WARNING - /home/airflow/.local/lib/python3.12/site-packages/airflow/task/task_runner/standard_task_runner.py:61: DeprecationWarning: This process (pid=670) is multi-threaded, use of fork() may lead to deadlocks in the child.
  pid = os.fork()

[2024-07-11T07:26:40.148+0000] {standard_task_runner.py:63} INFO - Started process 678 to run task
[2024-07-11T07:26:40.150+0000] {standard_task_runner.py:90} INFO - Running: ['airflow', 'tasks', 'run', 'market_etl', 'upload_to_s3__2', 'manual__2024-07-11T07:10:19.817387+00:00', '--job-id', '989', '--raw', '--subdir', 'DAGS_FOLDER/etl.py', '--cfg-path', '/tmp/tmp0dhh_p6u']
[2024-07-11T07:26:40.153+0000] {standard_task_runner.py:91} INFO - Job 989: Subtask upload_to_s3__2
[2024-07-11T07:26:40.227+0000] {task_command.py:426} INFO - Running <TaskInstance: market_etl.upload_to_s3__2 manual__2024-07-11T07:10:19.817387+00:00 [running]> on host aa283b53dd54
[2024-07-11T07:26:40.455+0000] {taskinstance.py:2648} INFO - Exporting env vars: AIRFLOW_CTX_DAG_OWNER='airflow' AIRFLOW_CTX_DAG_ID='market_etl' AIRFLOW_CTX_TASK_ID='upload_to_s3__2' AIRFLOW_CTX_EXECUTION_DATE='2024-07-11T07:10:19.817387+00:00' AIRFLOW_CTX_TRY_NUMBER='1' AIRFLOW_CTX_DAG_RUN_ID='manual__2024-07-11T07:10:19.817387+00:00'
[2024-07-11T07:26:40.457+0000] {taskinstance.py:430} INFO - ::endgroup::
[2024-07-11T07:26:40.488+0000] {base.py:84} INFO - Using connection ID 'aws_default' for task execution.
[2024-07-11T07:26:40.489+0000] {connection_wrapper.py:387} INFO - AWS Connection (conn_id='aws_default', conn_type='aws') credentials retrieved from extra.
[2024-07-11T07:26:40.489+0000] {connection_wrapper.py:401} INFO - AWS Connection (conn_id='aws_default', conn_type='aws') session token retrieved from extra, please note you are responsible for renewing these.
[2024-07-11T07:26:41.972+0000] {taskinstance.py:441} INFO - ::group::Post task execution logs
[2024-07-11T07:26:41.979+0000] {taskinstance.py:2905} ERROR - Task failed with exception
Traceback (most recent call last):
  File "/home/airflow/.local/lib/python3.12/site-packages/airflow/models/taskinstance.py", line 465, in _execute_task
    result = _execute_callable(context=context, **execute_callable_kwargs)
             ^^^^^^^^^^^^^^^^^^^^^^^^^^^^^^^^^^^^^^^^^^^^^^^^^^^^^^^^^^^^^
  File "/home/airflow/.local/lib/python3.12/site-packages/airflow/models/taskinstance.py", line 432, in _execute_callable
    return execute_callable(context=context, **execute_callable_kwargs)
           ^^^^^^^^^^^^^^^^^^^^^^^^^^^^^^^^^^^^^^^^^^^^^^^^^^^^^^^^^^^^
  File "/home/airflow/.local/lib/python3.12/site-packages/airflow/models/baseoperator.py", line 401, in wrapper
    return func(self, *args, **kwargs)
           ^^^^^^^^^^^^^^^^^^^^^^^^^^^
  File "/home/airflow/.local/lib/python3.12/site-packages/airflow/decorators/base.py", line 265, in execute
    return_value = super().execute(context)
                   ^^^^^^^^^^^^^^^^^^^^^^^^
  File "/home/airflow/.local/lib/python3.12/site-packages/airflow/models/baseoperator.py", line 401, in wrapper
    return func(self, *args, **kwargs)
           ^^^^^^^^^^^^^^^^^^^^^^^^^^^
  File "/home/airflow/.local/lib/python3.12/site-packages/airflow/operators/python.py", line 235, in execute
    return_value = self.execute_callable()
                   ^^^^^^^^^^^^^^^^^^^^^^^
  File "/home/airflow/.local/lib/python3.12/site-packages/airflow/operators/python.py", line 252, in execute_callable
    return self.python_callable(*self.op_args, **self.op_kwargs)
           ^^^^^^^^^^^^^^^^^^^^^^^^^^^^^^^^^^^^^^^^^^^^^^^^^^^^^
  File "/opt/airflow/dags/etl.py", line 145, in upload_to_s3
    s3_hook.load_string(
  File "/home/airflow/.local/lib/python3.12/site-packages/airflow/providers/amazon/aws/hooks/s3.py", line 135, in wrapper
    return func(*bound_args.args, **bound_args.kwargs)
           ^^^^^^^^^^^^^^^^^^^^^^^^^^^^^^^^^^^^^^^^^^^
  File "/home/airflow/.local/lib/python3.12/site-packages/airflow/providers/amazon/aws/hooks/s3.py", line 89, in wrapper
    return func(*bound_args.args, **bound_args.kwargs)
           ^^^^^^^^^^^^^^^^^^^^^^^^^^^^^^^^^^^^^^^^^^^
  File "/home/airflow/.local/lib/python3.12/site-packages/airflow/providers/amazon/aws/hooks/s3.py", line 1149, in load_string
    self._upload_file_obj(f, key, bucket_name, replace, encrypt, acl_policy)
  File "/home/airflow/.local/lib/python3.12/site-packages/airflow/providers/amazon/aws/hooks/s3.py", line 1232, in _upload_file_obj
    client.upload_fileobj(
  File "/home/airflow/.local/lib/python3.12/site-packages/boto3/s3/inject.py", line 642, in upload_fileobj
    return future.result()
           ^^^^^^^^^^^^^^^
  File "/home/airflow/.local/lib/python3.12/site-packages/s3transfer/futures.py", line 103, in result
    return self._coordinator.result()
           ^^^^^^^^^^^^^^^^^^^^^^^^^^
  File "/home/airflow/.local/lib/python3.12/site-packages/s3transfer/futures.py", line 266, in result
    raise self._exception
  File "/home/airflow/.local/lib/python3.12/site-packages/s3transfer/tasks.py", line 139, in __call__
    return self._execute_main(kwargs)
           ^^^^^^^^^^^^^^^^^^^^^^^^^^
  File "/home/airflow/.local/lib/python3.12/site-packages/s3transfer/tasks.py", line 162, in _execute_main
    return_value = self._main(**kwargs)
                   ^^^^^^^^^^^^^^^^^^^^
  File "/home/airflow/.local/lib/python3.12/site-packages/s3transfer/upload.py", line 764, in _main
    client.put_object(Bucket=bucket, Key=key, Body=body, **extra_args)
  File "/home/airflow/.local/lib/python3.12/site-packages/botocore/client.py", line 565, in _api_call
    return self._make_api_call(operation_name, kwargs)
           ^^^^^^^^^^^^^^^^^^^^^^^^^^^^^^^^^^^^^^^^^^^
  File "/home/airflow/.local/lib/python3.12/site-packages/botocore/client.py", line 1021, in _make_api_call
    raise error_class(parsed_response, operation_name)
botocore.exceptions.ClientError: An error occurred (InvalidAccessKeyId) when calling the PutObject operation: The AWS Access Key Id you provided does not exist in our records.
[2024-07-11T07:26:42.040+0000] {taskinstance.py:1206} INFO - Marking task as UP_FOR_RETRY. dag_id=market_etl, task_id=upload_to_s3__2, run_id=manual__2024-07-11T07:10:19.817387+00:00, execution_date=20240711T071019, start_date=20240711T072640, end_date=20240711T072642
[2024-07-11T07:26:42.081+0000] {standard_task_runner.py:110} ERROR - Failed to execute job 989 for task upload_to_s3__2 (An error occurred (InvalidAccessKeyId) when calling the PutObject operation: The AWS Access Key Id you provided does not exist in our records.; 678)
[2024-07-11T07:26:42.098+0000] {local_task_job_runner.py:240} INFO - Task exited with return code 1
[2024-07-11T07:26:42.177+0000] {taskinstance.py:3503} INFO - 0 downstream tasks scheduled from follow-on schedule check
[2024-07-11T07:26:42.178+0000] {local_task_job_runner.py:222} INFO - ::endgroup::
